Workbook
Name \p: #REF!
Name \p: #REF!
Name \p: #REF!
Name \p: #REF!
Name _010SpotSales: #REF!
Name _011OffMktSales: #REF!
Name _012EnergySalesComalco: #REF!
Name _013Direct_Supply: #REF!
Name _015_Energy_Sales_ECNZ_Hedges: #REF!
Name _017_EnergyTransmissionRev_TP: #REF!
Name _019Discounts: #REF!
Name _01GEnergy_Sales_ECNZ_Buy_Hedges: #REF!
Name _01H_EnergySales_Other_Hedges: #REF!
Name _01I_EnergySales_InternalHedge: #REF!
Name _01R_EnergySales_ExistingRetail: #REF!
Name _01T_EnergySales_TransaltaLease: #REF!
Name _020_EnergyFuturesTrading: #REF!
Name _051_Lease_RentalIncome: #REF!
Name _052_DividendsIncome: #REF!
Name _053_GainonForeignCurrency: #REF!
Name _054_GainonSaleofFixedAssets: #REF!
Name _055_MiscellaneousIncome: #REF!
Name _070_Steam_HotWaterRevenues: #REF!
Name _112_NZEMCosts_ServiceProvider: #REF!
Name _113_MACSCosts: #REF!
Name _115_Connection_OtherCharges: #REF!
Name _118EnergyCostComalco: #REF!
Name _119Energy_Cost_Direct_Supply: #REF!
Name _11A_MeterReading_TOU: #REF!
Name _11B_MeterLeasing: #REF!
Name _11C_MeterManagement: #REF!
Name _11D_RocMeterReading: #REF!
Name _11MComalcoTransmissionRevenue: #REF!
Name _11N_TiwaiPointTransCharge: #REF!
Name _11P_LineRevenue: #REF!
Name _11QLineCharges: #REF!
Name _120_MARIACosts: #REF!
Name _121AC_ConnectionCharges: #REF!
Name _122HVDC_Charges: #REF!
Name _123_InvoiceProcessing: #REF!
Name _124_RemittanceProcessing: #REF!
Name _125_DataAdministration: #REF!
Name _126_ROCAdministrativeStaff: #REF!
Name _127_ROCCallCentreStaff: #REF!
Name _190_GridExitPoints: #REF!
Name _191_FieldServicescosts: #REF!
Name _192_PulseCosts: #REF!
Name _1HOLOS_ORIENT_P_L_ACT_DL: #REF!
Name _211_Salary_Pay: #REF!
Name _212_Bonus: #REF!
Name _213_TempEmployeesWages: #REF!
Name _214_CapitalisedSalary: #REF!
Name _221_AccidentInsurance: #REF!
Name _223_FringeBenefitTax: #REF!
Name _224_MembershipFees_Staff: #REF!
Name _225_Severance: #REF!
Name _231_RecruitmentCosts: #REF!
Name _241_Training_Conferencecosts: #REF!
Name _242_Training_TRAVEL_ACCOMMcosts: #REF!
Name _251_HumanResourcePrograms: #REF!

Sheet Summary
A1: Fiscal Time Series Historical Indicators 1972 - 2025
A2: Update for Year End 30 June 2025
A3: Published 9 January 2026
A4: Published by the Treasury at https://www.treasury.govt.nz/publications/information-release/data-fiscal-time-series-historical-fiscal-indicators
A6: Click on a group title to access an explanation of the series contained in that group.

Sheet Series Descriptions
B1: Series Descriptions
A140: Magnitude of difference in 1994 transition from cash to accrual
A142: Series | C142: Cash, GST inclusive | D142: Accrual (old-GAAP), GST exclusive | E142: Difference | F142: Notes
A143: Expenses by Function Classification
B144: Social security and welfare, GSF | C144: 10528 | D144: 11473 | E144: =C144-D144 -> -945
B145: Health | C145: 4103 | D145: 4104 | E145: =C145-D145 -> -1
B146: Education | C146: 4631 | D146: 4173 | E146: =C146-D146 -> 458
B147: Core Government Services | C147: 2104 | D147: 1673 | E147: =C147-D147 -> 431
B148: Law and order | C148: 1260 | D148: 1145 | E148: =C148-D148 -> 115
B149: Defence | C149: 1163 | D149: 1049 | E149: =C149-D149 -> 114
B150: Transport and communications | C150: 805 | D150: 733 | E150: =C150-D150 -> 72
B151: Economic and Industrial Services | C151: 909 | D151: 653 | E151: =C151-D151 -> 256
B152: Heritage, culture and recreation; Primary Services, Housing and community development, Other | C152: 114 | D152: 583 | E152: =C152-D152 -> -469 | F152: Relatively large difference due differences in functional classifications
B153: Finance costs | C153: 3557 | D153: 3788 | E153: =C153-D153 -> -231
A155: Financial Net Expenditure (cash)/Core Crown Expenses (accrual) | C155: 29174 | D155: 28476 | E155: =C155-D155 -> 698 | F155: Adding FX net losses of $898m to sum of expenses by function gives core Crown Expenses.
A157: Cash Receipts (cash)/Core Crown Revenue (accrual) | C157: 29598 | D157: 29020 | E157: =C157-D157 -> 578
A159: Adjusted Financial Balance (cash)/Total Crown Operating Balance (accrual) | C159: 792 | D159: 755 | E159: =C159-D159 -> 37 | F159: A full line-by-line reconciliation of the Adjusted Financial Balance can be found in Table 1 on page 6 of the "Fiscal Time Series Explanatory Note".

Sheet Sources
A1: Sources

Sheet Spending
A1: Spending
A3: $ millions | C3: Spending | G3: Core Crown Expense Classes
C4: Financial Net Expenditure | D4: Core Crown Expenses | E4: Total Crown Expenses | G4: Social security and welfare, GSF | H4: Health | I4: Education | J4: Core Government Services | K4: Law and order | L4: Defence | M4: Transport and communications | N4: Economic and Industrial Services | O4: Heritage, culture and recreation; Primary Services, Housing and community development, Environemntal protection, Other | P4: Finance costs | Q4: Net foreign exchange gains(-)/losses
A5: Cash, March Years | B5: 1972 | C5: 1682.8 | G5: 391.9 | H5: 291.8 | I5: 335 | J5: 113.8 | K5: 32.2 | L5: 118.8 | M5: 144.4 | N5: 43.3 | O5: 131.6 | P5: 168
B6: 1973 | C6: 2006.2 | G6: 527.3 | H6: 343.1 | I6: 376.8 | J6: 133.3 | K6: 39.8 | L6: 128.1 | M6: 183.1 | N6: 68.7 | O6: 143.5 | P6: 186.5
B7: 1974 | C7: 2303.9 | G7: 646.8 | H7: 401.1 | I7: 440.2 | J7: 168 | K7: 46.3 | L7: 138.7 | M7: 168.7 | N7: 75.2 | O7: 194.8 | P7: 201.9
B8: 1975 | C8: 2977.7 | G8: 789.5 | H8: 492.3 | I8: 526.6 | J8: 228.4 | K8: 61 | L8: 163 | M8: 211.2 | N8: 145.3 | O8: 313.5 | P8: 221.8
B9: 1976 | C9: 3562 | G9: 997 | H9: 605.7 | I9: 627 | J9: 272.7 | K9: 77.8 | L9: 188.4 | M9: 274.8 | N9: 228.4 | O9: 494.1 | P9: 272.8
B10: 1977 | C10: 3956.9 | G10: 1158.9 | H10: 689.1 | I10: 699.4 | J10: 315.2 | K10: 79.6 | L10: 210.7 | M10: 230.6 | N10: 293.2 | O10: 283.2 | P10: 371.3
B11: 1978 | C11: 4959.1 | G11: 1569.3 | H11: 808.5 | I11: 807.5 | J11: 337.7 | K11: 107.5 | L11: 248.2 | M11: 247.6 | N11: 375.9 | O11: 368.7 | P11: 471.3
B12: 1979 | C12: 6099.5 | G12: 1853.5 | H12: 980.1 | I12: 929.3 | J12: 420 | K12: 139.3 | L12: 293.2 | M12: 279.1 | N12: 486.1 | O12: 507.5 | P12: 595.8
B13: 1980 | C13: 6971.2 | G13: 2175 | H13: 1136.2 | I13: 1009.3 | J13: 467.7 | K13: 164.7 | L13: 340.8 | M13: 265 | N13: 398.5 | O13: 486.6 | P13: 766.4
B14: 1981 | C14: 8517.3 | G14: 2589.7 | H14: 1356.3 | I14: 1292 | J14: 568.4 | K14: 208.8 | L14: 446.4 | M14: 332.6 | N14: 434.7 | O14: 502.5 | P14: 896.9
B15: 1982 | C15: 10407.7 | G15: 3042.3 | H15: 1601.2 | I15: 1493.2 | J15: 673 | K15: 253.5 | L15: 581.1 | M15: 460.6 | N15: 652.4 | O15: 657.7 | P15: 1211
B16: 1983 | C16: 11956.4 | G16: 3744.2 | H16: 1766 | I16: 1638.8 | J16: 707.1 | K16: 266.3 | L16: 644.1 | M16: 495.6 | N16: 742.1 | O16: 710.9 | P16: 1492.6
B17: 1984 | C17: 13424.6 | G17: 4049.4 | H17: 1804.9 | I17: 1674.3 | J17: 729.2 | K17: 271.3 | L17: 660.2 | M17: 537.1 | N17: 896.2 | O17: 996.1 | P17: 2041.9
... B19: 1986 | C19: 16987.2 | G19: 5449.1 | H19: 2309 | I19: 2010.3 | J19: 1048.2 | K19: 391.1 | L19: 852.1 | M19: 865.6 | N19: 755.2 | O19: 460.8 | P19: 3340
B20: 1987† | C20: 20823 | G20: 6479.3 | H20: 2957.3 | I20: 2595.2 | J20: 1205.6 | K20: 520.6 | L20: 1072.1 | M20: 1039.4 | N20: 1007.5 | O20: 476.4 | P20: 4091.9
B21: 1988† | C21: 24905.7 | G21: 7791.9 | H21: 3387.5 | I21: 3118.2 | J21: 1798.2 | K21: 681.4 | L21: 1257.6 | M21: 654.8 | N21: 1006.6 | O21: 343 | P21: 4970.9
B22: 1989† | C22: 26427.5 | G22: 9123.3 | H22: 3639.3 | I22: 3569.2 | J22: 1886.1 | K22: 863.7 | L22: 1366.9 | M22: 672 | N22: 872.1 | O22: 355.7 | P22: 4492.5
A23: Cash, June Years | B23: 1990† | C23: 29294.4 | G23: 10319.8 | H23: 3782.2 | I23: 4068.2 | J23: 2376.5 | K23: 958.7 | L23: 1352.3 | M23: 888.3 | N23: 870.2 | O23: 289.3 | P23: 4724.5
B24: 1991† | C24: 30298 | G24: 10317 | H24: 3986 | I24: 4401 | J24: 2446.9 | K24: 1003.9 | L24: 1319.2 | M24: 826 | N24: 1038.8 | O24: 335.2 | P24: 4624
B25: 1992† | C25: 29174 | G25: 10620 | H25: 3855 | I25: 4467 | J25: 2084.7 | K25: 1036.3 | L25: 1238 | M25: 816 | N25: 640.7 | O25: 269.3 | P25: 4147
B26: 1993† | C26: 29418 | G26: 10697.2 | H26: 3873.6 | I26: 4503.6 | J26: 2179.1 | K26: 1281.4 | L26: 1171.4 | M26: 717.6 | N26: 944.1 | O26: 149.9 | P26: 3898.5
A27: old-GAAP | B27: 1994* | D27: 28476 | G27: =10725+748 -> 11473 | H27: 4104 | I27: 4173 | J27: 1673 | K27: =1145 -> 1145 | L27: 1049 | M27: 733 | N27: 653 | O27: 583 | P27: 3788 | Q27: -898
B28: 1995* | D28: 29214 | G28: =10851+872 -> 11723 | H28: 4367 | I28: 4338 | J28: 1300 | K28: 1176 | L28: 1013 | M28: 714 | N28: 622 | O28: 755 | P28: 3757 | Q28: -551
B29: 1996* | D29: 30483 | G29: =11230+1009 -> 12239 | H29: 4672 | I29: 4463 | J29: 1508 | K29: 1222 | L29: 970 | M29: 737 | N29: 950 | O29: 622 | P29: 3703 | Q29: -603
A30: IFRS, June Years | B30: 1997 | D30: 31367.962 | E30: 37599.962 | G30: 12180.962 | H30: 5029 | I30: 4817 | J30: 1956 | K30: 1266 | L30: 946 | M30: 797 | N30: 711 | O30: 720 | P30: 2945
B31: 1998 | D31: 32981.947 | E31: 38766.947 | G31: 13024.947 | H31: 5361 | I31: 5162 | J31: 1858 | K31: 1329 | L31: 1065 | M31: 850 | N31: 769 | O31: 890 | P31: 2673
B32: 1999 | D32: 33938.571 | E32: 39837.571 | G32: 13435.571 | H32: 5875 | I32: 5337 | J32: 1984 | K32: 1482 | L32: 1022 | M32: 923 | N32: 813 | O32: 700 | P32: 2367
B33: 2000 | D33: 34828.526 | E33: 41017.946 | G33: 13499.526 | H33: 6146 | I33: 5712 | J33: 1992 | K33: 1509 | L33: 1163 | M33: 929 | N33: 881 | O33: 792 | P33: 2205
B34: 2001^ | D34: 36558.549 | E34: 43518.019 | G34: 13781.549 | H34: 6660 | I34: 6136 | J34: 2148 | K34: 1541 | L34: 1242 | M34: 905 | N34: 1037 | O34: 804 | P34: 2304
B35: 2002^ | D35: 37512.702 | E35: 47202.446 | G35: 14161.406 | H35: 7032 | I35: 6473 | J35: 1890 | K35: 1733 | L35: 1162 | M35: 989 | N35: 1013 | O35: 941.296 | P35: 2118
B36: 2003^ | D36: 39897.483 | E36: 51948.612 | G36: 14448.87 | H36: 7501 | I36: 7016 | J36: 2130 | K36: 1734 | L36: 1199 | M36: 1408 | N36: 1054 | O36: 1046.613 | P36: 2360
B37: 2004^ | D37: 41882.174 | E37: 53210.765 | G37: 14843.556 | H37: 8111 | I37: 7585 | J37: 2091 | K37: 1843 | L37: 1311 | M37: 1461 | N37: 1192 | O37: 1192.618 | P37: 2252
A38: PBE Standards, June Years | B38: 2005^ | D38: 44660 | E38: 57687 | G38: 15253 | H38: 8813 | I38: 7930 | J38: 2567 | K38: 1889 | L38: 1275 | M38: 1635 | N38: 1444 | O38: 1580 | P38: 2274
B39: 2006^ | D39: 49084 | E39: 63703 | G39: 16212 | H39: 9547 | I39: 9914 | J39: 2507 | K39: 2146 | L39: 1383 | M39: 1818 | N39: 1592 | O39: 1609 | P39: 2356
B40: 2007^ | D40: 53764 | E40: 68055 | G40: 17266 | H40: 10355 | I40: 9269 | J40: 4817 | K40: 2606 | L40: 1517 | M40: 2405 | N40: 1595 | O40: 1605 | P40: 2329
B41: 2008^ | D41: 56753 | E41: 75096 | G41: 18420 | H41: 11297 | I41: 9551 | J41: 3371 | K41: 2797 | L41: 1562 | M41: 2244 | N41: 2889 | O41: 2162 | P41: 2460
B42: 2009^ | D42: 63711 | E42: 82592 | G42: 19844 | H42: 12368 | I42: 11455 | J42: 5293 | K42: 2992 | L42: 1757 | M42: 2663 | N42: 2960 | O42: 1950 | P42: 2429
...

Sheet Revenue, Surplus measures
A1: Surplus/Deficit, Revenue
A3: $ millions | C3: Surplus/Deficit Measures | I3: Tax and Revenue
C4: Adjusted Financial Balance | D4: Total Crown Operating Balance | E4: Total Crown OBEGALx | F4: Total Crown OBEGAL | G4: Core Crown Residual Cash | I4: Total Crown Tax Receipts | J4: Core Crown Tax Revenue | L4: Cash Receipts | M4: Core Crown Revenue | N4: Total Crown Revenue
A5: Cash, March Years | B5: 1972 | C5: 107.2 | I5: 1707 | L5: 1790
B6: 1973 | C6: 7.2 | I6: 1926.7 | L6: 2013.4
B7: 1974 | C7: 87.7 | I7: 2395 | L7: 2391.6
B8: 1975 | C8: 42.9 | I8: 2865.5 | L8: 3020.6
B9: 1976 | C9: -177.6 | I9: 3185.5 | L9: 3384.4
B10: 1977 | C10: 115.6 | I10: 3845.3 | L10: 4072.5
B11: 1978 | C11: 15.2 | I11: 4626.3 | L11: 4974.3
B12: 1979 | C12: -697.1 | I12: 4989.5 | L12: 5402.4
B13: 1980 | C13: -411.5 | I13: 6019.9 | L13: 6559.7
B14: 1981 | C14: -908.9 | I14: 7050.6 | L14: 7608.4
B15: 1982 | C15: -1029.3 | I15: 8798.2 | L15: 9378.4
B16: 1983 | C16: -1442 | I16: 10097.4 | L16: 10514.4
B17: 1984 | C17: -2275.1 | I17: 10431.4 | L17: 11149.5
... B19: 1986 | C19: -1185.9 | I19: 14235.9 | L19: 15801.3
B20: 1987† | C20: -1830.5 | I20: 17408.1 | L20: 18992.5
B21: 1988† | C21: -1322 | I21: 21528.1 | L21: 23583.7
B22: 1989† | C22: -954.1 | I22: 22864 | L22: 25473.4
A23: Cash, June Years | B23: 1990† | C23: -943.2 | I23: 26198.2 | L23: 28351.2
B24: 1991† | C24: -2558 | I24: 25797 | L24: 29010
B25: 1992† | C25: -2528 | I25: 24843 | L25: 27635
B26: 1993† | C26: -1823 | I26: 25980 | L26: 27629
A27: old-GAAP | B27: 1994* | D27: 755 | F27: -517 | G27: 679 | I27: 27571 | J27: 26542 | M27: 29020
B28: 1995* | D28: 2695 | F28: 2738 | G28: 396 | I28: 29961 | J28: 29026 | M28: 32461
B29: 1996* | D29: 3314 | F29: 2928 | G29: 4932 | I29: 32319 | J29: 30973 | M29: 33799
A30: IFRS, June Years | B30: 1997 | D30: 1863 | F30: 1801 | G30: 3913 | I30: 31731 | J30: 30737 | M30: 33130.962 | N30: 39400.962
B31: 1998 | D31: 2048 | F31: 2345 | G31: 484 | I31: 33059 | J31: 31779 | M31: 34241.947 | N31: 41111.947
B32: 1999 | D32: 1705 | F32: 128 | G32: 2048 | I32: 32384 | J32: 30875 | M32: 32879.571 | N32: 39965.571
B33: 2000 | D33: 1404.58 | F33: 593.58 | G33: -386 | I33: 33864 | J33: 32598 | M33: 34945.526 | N33: 41611.526
B34: 2001^ | D34: 1207.53 | F34: 1421.53 | G34: 349 | I34: 36250 | J34: 35345 | M34: 37841.549 | N34: 44939.549
B35: 2002^ | D35: 2286.4422 | F35: 2471.2152 | G35: 216 | I35: 38862 | J35: 36809 | M35: 39944.685 | N35: 49673.661
B36: 2003^ | D36: 1621.039 | F36: 4365.903 | G36: 1217 | I36: 39842 | J36: 40518 | M36: 43440.393 | N36: 56314.515
B37: 2004^ | D37: 7308.8377 | F37: 5573.1177 | G37: 520 | I37: 42777 | J37: 43358 | M37: 46219.472 | N37: 58783.883
A38: PBE Standards, June Years | B38: 2005^ | D38: 5930.9119 | F38: 7074.7859 | G38: 3104 | I38: 46867 | J38: 47468 | M38: 50809 | N38: 64761
B39: 2006^ | D39: 9541.6391 | F39: 7091.0254 | G39: 2985 | I39: 49706 | J39: 50973 | M39: 55499 | N39: 70794
B40: 2007^ | D40: 8022 | F40: 5860 | G40: 2793 | I40: 52157 | J40: 53477 | M40: 57971 | N40: 73915
B41: 2008^ | D41: 2384 | E41: 5793 | F41: 5637 | G41: 2057 | I41: 55168 | J41: 56747 | M41: 61575 | N41: 80733
B42: 2009^ | D42: -10505 | E42: -3800 | F42: -3893 | G42: -8639 | I42: 51119 | J42: 54681 | M42: 59191 | N42: 78699
...

Sheet Debt, Net Worth
A1: Gross Debt, Net Debt, Net Worth
A3: $ millions | C3: Gross Debt Measures | G3: Net Worth | J3: Net Debt Measures
C4: Total Crown Borrowings | D4: Gross Sovereign-issued Debt | E4: Gross debt | G4: Total Crown Net Worth | H4: Net Worth attributable to the Crown | J4: (Former) Core Crown Net Debt | K4: Core Crown Net Debt | L4: Net Debt
A5: Cash, March Years | B5: 1972 | D5: 3186.5 | E5: 3186.5 | J5: 405.083
B6: 1973 | D6: 3503.1 | E6: 3503.1 | J6: 466.983
B7: 1974 | D7: 3734.5 | E7: 3734.5 | J7: 408.695
B8: 1975 | D8: 4199.7 | E8: 4199.7 | J8: 501
B9: 1976 | D9: 5557.9 | E9: 5557.9 | J9: 985.8
B10: 1977 | D10: 6289.2 | E10: 6289.2 | J10: 1069.4
B11: 1978 | D11: 7483.8 | E11: 7483.8 | J11: 1339.3
B12: 1979 | D12: 8819.5 | E12: 8819.5 | J12: 2548.273
B13: 1980 | D13: 10346.4 | E13: 10346.4 | J13: 3226.4
B14: 1981 | D14: 11617.1 | E14: 11617.1 | J14: 4063.729
B15: 1982 | D15: 14381.4 | E15: 14381.4 | J15: 5903.384
B16: 1983 | D16: 18732.8 | E16: 18732.8 | J16: 8959.4
B17: 1984 | D17: 21878.7 | E17: 21878.7 | J17: 11029.37
... B22: 1989 | D22: 39721 | E22: 39721 | J22: 29933.637
A23: Cash, June Years | B23: 1990 | D23: 44347 | E23: 44347 | J23: 35705.695
B24: 1991 | D24: 43935 | E24: 43935 | J24: 34071.669
B25: 1992 | D25: 47105 | E25: 47105 | J25: 38414.798 | K25: 42171.798
B26: 1993 | D26: 47478 | E26: 47478 | J26: 37196 | K26: 40262
A27: IFRS, June Years | B27: 1994 | C27: 47873 | D27: 46429 | E27: 46429 | G27: -3294.9774 | J27: 35423 | K27: 38980
B28: 1995 | C28: 46145 | D28: 44529.609 | E28: 44529.609 | G28: 1438.8045 | J28: 32969.509 | K28: 38680.509
B29: 1996 | C29: 43663 | D29: 41900.731 | E29: 41900.731 | G29: 7991.1805 | J29: 28986.329 | K29: 33835.329
B30: 1997 | C30: 38968.273 | D30: 36236.273 | E30: 36236.273 | G30: 12167.053 | J30: 25561.781 | K30: 30316.781
B31: 1998 | C31: 40593.788 | D31: 38474.788 | E31: 38474.788 | G31: 14573.639 | J31: 24635.057 | K31: 30472.057
B32: 1999 | C32: 38715.333 | D32: 37307.333 | E32: 37307.333 | G32: 10792.992 | J32: 22274.782 | K32: 25922.782
B33: 2000 | C33: 37526.976 | D33: 36579.976 | E33: 36579.976 | G33: 12605.073 | J33: 21900.256 | K33: 25895.256
B34: 2001 | C34: 38129.834 | D34: 37193.834 | E34: 37193.834 | G34: 15450.219 | J34: 20292.976 | K34: 24907.976
B35: 2002 | C35: 38492.456 | D35: 36650.486 | E35: 36650.486 | G35: 22824.599 | H35: 22719 | J35: 19665.752 | K35: 25387.752
B36: 2003 | C36: 39327.22 | D36: 36617.22 | E36: 36617.22 | G36: 28012.28 | H36: 27918 | J36: 17976.723 | K36: 24530.723
B37: 2004 | C37: 37719.796 | D37: 36017.288 | E37: 36017.288 | G37: 39595.001 | H37: 39456 | J37: 15569.185 | K37: 23858.185
A38: PBE Standards, June Years | B38: 2005 | C38: 37728.361 | D38: 35477.834 | E38: 35477.834 | G38: 54240.469 | H38: 54025 | J38: 11092.976 | K38: 19878.976
B39: 2006 | C39: 40003.91 | D39: 35866.902 | E39: 33902.902 | G39: 83971 | H39: 83678 | J39: 8043.693 | K39: 16162.693
B40: 2007 | C40: 41898 | D40: 36805 | E40: 30647 | G40: 96827 | H40: 96458 | J40: 4109 | K40: 13380
B41: 2008 | C41: 46110 | D41: 37745 | E41: 31390 | G41: 105514 | H41: 105132 | J41: -19 | K41: 10258 | L41: -9479.943
B42: 2009 | C42: 61953 | D42: 50973 | E42: 43356 | G42: 99515 | H42: 99068 | J42: 6690 | K42: 17119 | L42: -1711.009
B43: 2010 | C43: 69733 | D43: 58891 | E43: 53591 | G43: 94988 | H43: 94586 | J43: 15871 | K43: 26738 | L43: 5124.895
B44: 2011 | C44: 90245 | D44: 77290 | E44: 72420 | G44: 80887 | H44: 80579 | J44: 28049 | K44: 40128 | L44: 14554.494
B45: 2012 | C45: 100534 | D45: 84168 | E45: 79635 | G45: 59780 | H45: 59348 | J45: 37347 | K45: 50671 | L45: 23893.395
...

Sheet NZS Fund series
A1: NZS Fund
A3: $ millions | C3: NZS Fund series
C4: NZS Fund Revenue | D4: Crown contributions to the NZS Fund | E4: NZS Fund Current Tax expense | F4: NZS Fund Other Expenses and movements* | G4: NZS Fund Gains/(losses) | H4: NZS Fund Net worth
A5: Cash, March Years | B5: 1972
B6: 1973
B7: 1974
B8: 1975
B9: 1976
B10: 1977
B11: 1978
B12: 1979
B13: 1980
B14: 1981
B15: 1982
B16: 1983
B17: 1984
... B22: 1989
A23: Cash, June Years | B23: 1990
B24: 1991
B25: 1992
B26: 1993
A27: IFRS, June Years | B27: 1994
B28: 1995
B29: 1996
B30: 1997
B31: 1998
B32: 1999
B33: 2000
B34: 2001
B35: 2002 | C35: 15 | D35: 600 | E35: 0 | F35: 0 | G35: 0 | H35: 615
B36: 2003 | C36: 69 | D36: 1200 | E36: 0 | F36: 0 | G36: 0 | H36: 1884
B37: 2004 | C37: 131 | D37: 1879 | E37: 77 | F37: 7 | G37: 146 | H37: 3956
A38: PBE Standards, June Years | B38: 2005 | C38: 191 | D38: 2107 | E38: 234 | F38: 22 | G38: 557 | H38: 6555
B39: 2006 | C39: 359 | D39: 2337 | E39: 468 | F39: 58 | G39: 1130 | H39: 9855
B40: 2007 | C40: 436 | D40: 2049 | E40: 707 | F40: -28 | G40: 1313 | H40: 12973
B41: 2008 | C41: 385 | D41: 2104 | E41: 237 | F41: 18 | G41: -995 | H41: 14212
B42: 2009 | C42: 383 | D42: 2243 | E42: 4 | F42: -349 | G42: -3495 | H42: 13688
B43: 2010 | C43: 433 | D43: 250 | E43: -27 | F43: 492 | G43: 1750 | H43: 15656
B44: 2011 | C44: 518 | D44: 0 | E44: 872 | F44: 168 | G44: 3518 | H44: 18652
B45: 2012 | C45: 539 | D45: 0 | E45: 160 | F45: 124 | G45: -204 | H45: 18703
...

Sheet Nominal GDP
A1: Gross Domestic Product
A3: $ millions | C3: Nominal GDP
A5: March Years | B5: 1972 | C5: 6990
B6: 1973 | C6: 8080
B7: 1974 | C7: 9361
B8: 1975 | C8: 10203
B9: 1976 | C9: 11506
B10: 1977 | C10: 13972
B11: 1978 | C11: 15667
B12: 1979 | C12: 17810
B13: 1980 | C13: 20546
B14: 1981 | C14: 23988
B15: 1982 | C15: 29028
B16: 1983 | C16: 33426
B17: 1984 | C17: 37253
... B22: 1989 | C22: 70629
A23: June Years | B23: 1990 | C23: 75140
B24: 1991 | C24: 75959
B25: 1992 | C25: 76924
B26: 1993 | C26: 79349
B27: 1994 | C27: 86031
B28: 1995 | C28: 91897
B29: 1996 | C29: 97568
B30: 1997 | C30: 102105
B31: 1998 | C31: 104918
B32: 1999 | C32: 108196
B33: 2000 | C33: 114664
B34: 2001 | C34: 122209
B35: 2002 | C35: 129943
... B58: 2025 | C58: 436103
